[2022-06-04 16:01:10,823] [ERROR] Internal Server Error: /admin/goods/goodstype/add/
Traceback (most recent call last):
  File "/home/lqs/.local/lib/python3.10/site-packages/django/core/handlers/exception.py", line 55, in inner
    response = get_response(request)
  File "/home/lqs/.local/lib/python3.10/site-packages/django/core/handlers/base.py", line 197, in _get_response
    response = wrapped_callback(request, *callback_args, **callback_kwargs)
  File "/home/lqs/.local/lib/python3.10/site-packages/django/contrib/admin/options.py", line 683, in wrapper
    return self.admin_site.admin_view(view)(*args, **kwargs)
  File "/home/lqs/.local/lib/python3.10/site-packages/django/utils/decorators.py", line 133, in _wrapped_view
    response = view_func(request, *args, **kwargs)
  File "/home/lqs/.local/lib/python3.10/site-packages/django/views/decorators/cache.py", line 62, in _wrapped_view_func
    response = view_func(request, *args, **kwargs)
  File "/home/lqs/.local/lib/python3.10/site-packages/django/contrib/admin/sites.py", line 242, in inner
    return view(request, *args, **kwargs)
  File "/home/lqs/.local/lib/python3.10/site-packages/django/contrib/admin/options.py", line 1885, in add_view
    return self.changeform_view(request, None, form_url, extra_context)
  File "/home/lqs/.local/lib/python3.10/site-packages/django/utils/decorators.py", line 46, in _wrapper
    return bound_method(*args, **kwargs)
  File "/home/lqs/.local/lib/python3.10/site-packages/django/utils/decorators.py", line 133, in _wrapped_view
    response = view_func(request, *args, **kwargs)
  File "/home/lqs/.local/lib/python3.10/site-packages/django/contrib/admin/options.py", line 1745, in changeform_view
    return self._changeform_view(request, object_id, form_url, extra_context)
  File "/home/lqs/.local/lib/python3.10/site-packages/django/contrib/admin/options.py", line 1797, in _changeform_view
    self.save_model(request, new_object, form, not add)
  File "/home/lqs/.local/lib/python3.10/site-packages/django/contrib/admin/options.py", line 1220, in save_model
    obj.save()
  File "/home/lqs/.local/lib/python3.10/site-packages/django/db/models/base.py", line 806, in save
    self.save_base(
  File "/home/lqs/.local/lib/python3.10/site-packages/django/db/models/base.py", line 857, in save_base
    updated = self._save_table(
  File "/home/lqs/.local/lib/python3.10/site-packages/django/db/models/base.py", line 1000, in _save_table
    results = self._do_insert(
  File "/home/lqs/.local/lib/python3.10/site-packages/django/db/models/base.py", line 1041, in _do_insert
    return manager._insert(
  File "/home/lqs/.local/lib/python3.10/site-packages/django/db/models/manager.py", line 85, in manager_method
    return getattr(self.get_queryset(), name)(*args, **kwargs)
  File "/home/lqs/.local/lib/python3.10/site-packages/django/db/models/query.py", line 1434, in _insert
    return query.get_compiler(using=using).execute_sql(returning_fields)
  File "/home/lqs/.local/lib/python3.10/site-packages/django/db/models/sql/compiler.py", line 1620, in execute_sql
    for sql, params in self.as_sql():
  File "/home/lqs/.local/lib/python3.10/site-packages/django/db/models/sql/compiler.py", line 1547, in as_sql
    value_rows = [
  File "/home/lqs/.local/lib/python3.10/site-packages/django/db/models/sql/compiler.py", line 1548, in <listcomp>
    [
  File "/home/lqs/.local/lib/python3.10/site-packages/django/db/models/sql/compiler.py", line 1549, in <listcomp>
    self.prepare_value(field, self.pre_save_val(field, obj))
  File "/home/lqs/.local/lib/python3.10/site-packages/django/db/models/sql/compiler.py", line 1497, in pre_save_val
    return field.pre_save(obj, add=True)
  File "/home/lqs/.local/lib/python3.10/site-packages/django/db/models/fields/files.py", line 316, in pre_save
    file.save(file.name, file.file, save=False)
  File "/home/lqs/.local/lib/python3.10/site-packages/django/db/models/fields/files.py", line 91, in save
    name = self.field.generate_filename(self.instance, name)
  File "/home/lqs/.local/lib/python3.10/site-packages/django/db/models/fields/files.py", line 336, in generate_filename
    return self.storage.generate_filename(filename)
  File "/home/lqs/.local/lib/python3.10/site-packages/django/utils/functional.py", line 258, in inner
    self._setup()
  File "/home/lqs/.local/lib/python3.10/site-packages/django/core/files/storage.py", line 413, in _setup
    self._wrapped = get_storage_class()()
  File "/home/lqs/.local/lib/python3.10/site-packages/django/core/files/storage.py", line 408, in get_storage_class
    return import_string(import_path or settings.DEFAULT_FILE_STORAGE)
  File "/home/lqs/.local/lib/python3.10/site-packages/django/utils/module_loading.py", line 30, in import_string
    return cached_import(module_path, class_name)
  File "/home/lqs/.local/lib/python3.10/site-packages/django/utils/module_loading.py", line 15, in cached_import
    import_module(module_path)
  File "/usr/lib/python3.10/importlib/__init__.py", line 126, in import_module
    return _bootstrap._gcd_import(name[level:], package, level)
  File "<frozen importlib._bootstrap>", line 1050, in _gcd_import
  File "<frozen importlib._bootstrap>", line 1027, in _find_and_load
  File "<frozen importlib._bootstrap>", line 1006, in _find_and_load_unlocked
  File "<frozen importlib._bootstrap>", line 688, in _load_unlocked
  File "<frozen importlib._bootstrap_external>", line 883, in exec_module
  File "<frozen importlib._bootstrap>", line 241, in _call_with_frames_removed
  File "/usr/local/lib/python3.10/dist-packages/django_aliyun_oss2_storage-0.1.2-py3.10.egg/aliyun_oss2_storage/backends.py", line 16, in <module>
    from oss2 import Auth, Service, BucketIterator, Bucket, ObjectIterator
  File "/usr/local/lib/python3.10/dist-packages/oss2-2.15.0-py3.10.egg/oss2/__init__.py", line 3, in <module>
    from . import models, exceptions, defaults
  File "/usr/local/lib/python3.10/dist-packages/oss2-2.15.0-py3.10.egg/oss2/models.py", line 9, in <module>
    from . import utils
  File "/usr/local/lib/python3.10/dist-packages/oss2-2.15.0-py3.10.egg/oss2/utils.py", line 25, in <module>
    import crcmod
ModuleNotFoundError: No module named 'crcmod'
[2022-06-04 16:01:10,826] [ERROR] "POST /admin/goods/goodstype/add/ HTTP/1.1" 500 282816
[2022-06-04 16:02:03,265] [ERROR] Internal Server Error: /admin/goods/goodstype/add/
Traceback (most recent call last):
  File "/home/lqs/.local/lib/python3.10/site-packages/django/core/handlers/exception.py", line 55, in inner
    response = get_response(request)
  File "/home/lqs/.local/lib/python3.10/site-packages/django/core/handlers/base.py", line 197, in _get_response
    response = wrapped_callback(request, *callback_args, **callback_kwargs)
  File "/home/lqs/.local/lib/python3.10/site-packages/django/contrib/admin/options.py", line 683, in wrapper
    return self.admin_site.admin_view(view)(*args, **kwargs)
  File "/home/lqs/.local/lib/python3.10/site-packages/django/utils/decorators.py", line 133, in _wrapped_view
    response = view_func(request, *args, **kwargs)
  File "/home/lqs/.local/lib/python3.10/site-packages/django/views/decorators/cache.py", line 62, in _wrapped_view_func
    response = view_func(request, *args, **kwargs)
  File "/home/lqs/.local/lib/python3.10/site-packages/django/contrib/admin/sites.py", line 242, in inner
    return view(request, *args, **kwargs)
  File "/home/lqs/.local/lib/python3.10/site-packages/django/contrib/admin/options.py", line 1885, in add_view
    return self.changeform_view(request, None, form_url, extra_context)
  File "/home/lqs/.local/lib/python3.10/site-packages/django/utils/decorators.py", line 46, in _wrapper
    return bound_method(*args, **kwargs)
  File "/home/lqs/.local/lib/python3.10/site-packages/django/utils/decorators.py", line 133, in _wrapped_view
    response = view_func(request, *args, **kwargs)
  File "/home/lqs/.local/lib/python3.10/site-packages/django/contrib/admin/options.py", line 1745, in changeform_view
    return self._changeform_view(request, object_id, form_url, extra_context)
  File "/home/lqs/.local/lib/python3.10/site-packages/django/contrib/admin/options.py", line 1797, in _changeform_view
    self.save_model(request, new_object, form, not add)
  File "/home/lqs/.local/lib/python3.10/site-packages/django/contrib/admin/options.py", line 1220, in save_model
    obj.save()
  File "/home/lqs/.local/lib/python3.10/site-packages/django/db/models/base.py", line 806, in save
    self.save_base(
  File "/home/lqs/.local/lib/python3.10/site-packages/django/db/models/base.py", line 857, in save_base
    updated = self._save_table(
  File "/home/lqs/.local/lib/python3.10/site-packages/django/db/models/base.py", line 1000, in _save_table
    results = self._do_insert(
  File "/home/lqs/.local/lib/python3.10/site-packages/django/db/models/base.py", line 1041, in _do_insert
    return manager._insert(
  File "/home/lqs/.local/lib/python3.10/site-packages/django/db/models/manager.py", line 85, in manager_method
    return getattr(self.get_queryset(), name)(*args, **kwargs)
  File "/home/lqs/.local/lib/python3.10/site-packages/django/db/models/query.py", line 1434, in _insert
    return query.get_compiler(using=using).execute_sql(returning_fields)
  File "/home/lqs/.local/lib/python3.10/site-packages/django/db/models/sql/compiler.py", line 1620, in execute_sql
    for sql, params in self.as_sql():
  File "/home/lqs/.local/lib/python3.10/site-packages/django/db/models/sql/compiler.py", line 1547, in as_sql
    value_rows = [
  File "/home/lqs/.local/lib/python3.10/site-packages/django/db/models/sql/compiler.py", line 1548, in <listcomp>
    [
  File "/home/lqs/.local/lib/python3.10/site-packages/django/db/models/sql/compiler.py", line 1549, in <listcomp>
    self.prepare_value(field, self.pre_save_val(field, obj))
  File "/home/lqs/.local/lib/python3.10/site-packages/django/db/models/sql/compiler.py", line 1497, in pre_save_val
    return field.pre_save(obj, add=True)
  File "/home/lqs/.local/lib/python3.10/site-packages/django/db/models/fields/files.py", line 316, in pre_save
    file.save(file.name, file.file, save=False)
  File "/home/lqs/.local/lib/python3.10/site-packages/django/db/models/fields/files.py", line 91, in save
    name = self.field.generate_filename(self.instance, name)
  File "/home/lqs/.local/lib/python3.10/site-packages/django/db/models/fields/files.py", line 336, in generate_filename
    return self.storage.generate_filename(filename)
  File "/home/lqs/.local/lib/python3.10/site-packages/django/utils/functional.py", line 258, in inner
    self._setup()
  File "/home/lqs/.local/lib/python3.10/site-packages/django/core/files/storage.py", line 413, in _setup
    self._wrapped = get_storage_class()()
  File "/home/lqs/.local/lib/python3.10/site-packages/django/core/files/storage.py", line 408, in get_storage_class
    return import_string(import_path or settings.DEFAULT_FILE_STORAGE)
  File "/home/lqs/.local/lib/python3.10/site-packages/django/utils/module_loading.py", line 30, in import_string
    return cached_import(module_path, class_name)
  File "/home/lqs/.local/lib/python3.10/site-packages/django/utils/module_loading.py", line 15, in cached_import
    import_module(module_path)
  File "/usr/lib/python3.10/importlib/__init__.py", line 126, in import_module
    return _bootstrap._gcd_import(name[level:], package, level)
  File "<frozen importlib._bootstrap>", line 1050, in _gcd_import
  File "<frozen importlib._bootstrap>", line 1027, in _find_and_load
  File "<frozen importlib._bootstrap>", line 1006, in _find_and_load_unlocked
  File "<frozen importlib._bootstrap>", line 688, in _load_unlocked
  File "<frozen importlib._bootstrap_external>", line 883, in exec_module
  File "<frozen importlib._bootstrap>", line 241, in _call_with_frames_removed
  File "/usr/local/lib/python3.10/dist-packages/django_aliyun_oss2_storage-0.1.2-py3.10.egg/aliyun_oss2_storage/backends.py", line 16, in <module>
    from oss2 import Auth, Service, BucketIterator, Bucket, ObjectIterator
  File "/usr/local/lib/python3.10/dist-packages/oss2-2.15.0-py3.10.egg/oss2/__init__.py", line 3, in <module>
    from . import models, exceptions, defaults
  File "/usr/local/lib/python3.10/dist-packages/oss2-2.15.0-py3.10.egg/oss2/models.py", line 9, in <module>
    from . import utils
  File "/usr/local/lib/python3.10/dist-packages/oss2-2.15.0-py3.10.egg/oss2/utils.py", line 32, in <module>
    from Crypto.Cipher import AES
ModuleNotFoundError: No module named 'Crypto'
[2022-06-04 16:02:03,266] [ERROR] "POST /admin/goods/goodstype/add/ HTTP/1.1" 500 284621
[2022-06-04 16:20:06,974] [ERROR] Internal Server Error: /admin/goods/goodstype/add/
Traceback (most recent call last):
  File "/home/lqs/桌面/fresh-plus/dfresh/venv/lib/python3.10/site-packages/django/core/handlers/exception.py", line 47, in inner
    response = get_response(request)
  File "/home/lqs/桌面/fresh-plus/dfresh/venv/lib/python3.10/site-packages/django/core/handlers/base.py", line 181, in _get_response
    response = wrapped_callback(request, *callback_args, **callback_kwargs)
  File "/home/lqs/桌面/fresh-plus/dfresh/venv/lib/python3.10/site-packages/django/contrib/admin/options.py", line 622, in wrapper
    return self.admin_site.admin_view(view)(*args, **kwargs)
  File "/home/lqs/桌面/fresh-plus/dfresh/venv/lib/python3.10/site-packages/django/utils/decorators.py", line 130, in _wrapped_view
    response = view_func(request, *args, **kwargs)
  File "/home/lqs/桌面/fresh-plus/dfresh/venv/lib/python3.10/site-packages/django/views/decorators/cache.py", line 56, in _wrapped_view_func
    response = view_func(request, *args, **kwargs)
  File "/home/lqs/桌面/fresh-plus/dfresh/venv/lib/python3.10/site-packages/django/contrib/admin/sites.py", line 236, in inner
    return view(request, *args, **kwargs)
  File "/home/lqs/桌面/fresh-plus/dfresh/venv/lib/python3.10/site-packages/django/contrib/admin/options.py", line 1670, in add_view
    return self.changeform_view(request, None, form_url, extra_context)
  File "/home/lqs/桌面/fresh-plus/dfresh/venv/lib/python3.10/site-packages/django/utils/decorators.py", line 43, in _wrapper
    return bound_method(*args, **kwargs)
  File "/home/lqs/桌面/fresh-plus/dfresh/venv/lib/python3.10/site-packages/django/utils/decorators.py", line 130, in _wrapped_view
    response = view_func(request, *args, **kwargs)
  File "/home/lqs/桌面/fresh-plus/dfresh/venv/lib/python3.10/site-packages/django/contrib/admin/options.py", line 1549, in changeform_view
    return self._changeform_view(request, object_id, form_url, extra_context)
  File "/home/lqs/桌面/fresh-plus/dfresh/venv/lib/python3.10/site-packages/django/contrib/admin/options.py", line 1599, in _changeform_view
    self.save_model(request, new_object, form, not add)
  File "/home/lqs/桌面/fresh-plus/dfresh/venv/lib/python3.10/site-packages/django/contrib/admin/options.py", line 1108, in save_model
    obj.save()
  File "/home/lqs/桌面/fresh-plus/dfresh/venv/lib/python3.10/site-packages/django/db/models/base.py", line 743, in save
    self.save_base(using=using, force_insert=force_insert,
  File "/home/lqs/桌面/fresh-plus/dfresh/venv/lib/python3.10/site-packages/django/db/models/base.py", line 780, in save_base
    updated = self._save_table(
  File "/home/lqs/桌面/fresh-plus/dfresh/venv/lib/python3.10/site-packages/django/db/models/base.py", line 885, in _save_table
    results = self._do_insert(cls._base_manager, using, fields, returning_fields, raw)
  File "/home/lqs/桌面/fresh-plus/dfresh/venv/lib/python3.10/site-packages/django/db/models/base.py", line 923, in _do_insert
    return manager._insert(
  File "/home/lqs/桌面/fresh-plus/dfresh/venv/lib/python3.10/site-packages/django/db/models/manager.py", line 85, in manager_method
    return getattr(self.get_queryset(), name)(*args, **kwargs)
  File "/home/lqs/桌面/fresh-plus/dfresh/venv/lib/python3.10/site-packages/django/db/models/query.py", line 1301, in _insert
    return query.get_compiler(using=using).execute_sql(returning_fields)
  File "/home/lqs/桌面/fresh-plus/dfresh/venv/lib/python3.10/site-packages/django/db/models/sql/compiler.py", line 1440, in execute_sql
    for sql, params in self.as_sql():
  File "/home/lqs/桌面/fresh-plus/dfresh/venv/lib/python3.10/site-packages/django/db/models/sql/compiler.py", line 1382, in as_sql
    value_rows = [
  File "/home/lqs/桌面/fresh-plus/dfresh/venv/lib/python3.10/site-packages/django/db/models/sql/compiler.py", line 1383, in <listcomp>
    [self.prepare_value(field, self.pre_save_val(field, obj)) for field in fields]
  File "/home/lqs/桌面/fresh-plus/dfresh/venv/lib/python3.10/site-packages/django/db/models/sql/compiler.py", line 1383, in <listcomp>
    [self.prepare_value(field, self.pre_save_val(field, obj)) for field in fields]
  File "/home/lqs/桌面/fresh-plus/dfresh/venv/lib/python3.10/site-packages/django/db/models/sql/compiler.py", line 1334, in pre_save_val
    return field.pre_save(obj, add=True)
  File "/home/lqs/桌面/fresh-plus/dfresh/venv/lib/python3.10/site-packages/django/db/models/fields/files.py", line 302, in pre_save
    file.save(file.name, file.file, save=False)
  File "/home/lqs/桌面/fresh-plus/dfresh/venv/lib/python3.10/site-packages/django/db/models/fields/files.py", line 88, in save
    name = self.field.generate_filename(self.instance, name)
  File "/home/lqs/桌面/fresh-plus/dfresh/venv/lib/python3.10/site-packages/django/db/models/fields/files.py", line 322, in generate_filename
    return self.storage.generate_filename(filename)
  File "/home/lqs/桌面/fresh-plus/dfresh/venv/lib/python3.10/site-packages/django/utils/functional.py", line 248, in inner
    self._setup()
  File "/home/lqs/桌面/fresh-plus/dfresh/venv/lib/python3.10/site-packages/django/core/files/storage.py", line 370, in _setup
    self._wrapped = get_storage_class()()
  File "/home/lqs/桌面/fresh-plus/dfresh/venv/lib/python3.10/site-packages/django/core/files/storage.py", line 365, in get_storage_class
    return import_string(import_path or settings.DEFAULT_FILE_STORAGE)
  File "/home/lqs/桌面/fresh-plus/dfresh/venv/lib/python3.10/site-packages/django/utils/module_loading.py", line 30, in import_string
    return cached_import(module_path, class_name)
  File "/home/lqs/桌面/fresh-plus/dfresh/venv/lib/python3.10/site-packages/django/utils/module_loading.py", line 15, in cached_import
    import_module(module_path)
  File "/usr/lib/python3.10/importlib/__init__.py", line 126, in import_module
    return _bootstrap._gcd_import(name[level:], package, level)
  File "<frozen importlib._bootstrap>", line 1050, in _gcd_import
  File "<frozen importlib._bootstrap>", line 1027, in _find_and_load
  File "<frozen importlib._bootstrap>", line 1006, in _find_and_load_unlocked
  File "<frozen importlib._bootstrap>", line 688, in _load_unlocked
  File "<frozen importlib._bootstrap_external>", line 883, in exec_module
  File "<frozen importlib._bootstrap>", line 241, in _call_with_frames_removed
  File "/home/lqs/桌面/fresh-plus/dfresh/venv/lib/python3.10/site-packages/aliyun_oss2_storage/backends.py", line 15, in <module>
    from django.utils.encoding import force_text, filepath_to_uri, force_bytes
ImportError: cannot import name 'force_text' from 'django.utils.encoding' (/home/lqs/桌面/fresh-plus/dfresh/venv/lib/python3.10/site-packages/django/utils/encoding.py)
[2022-06-04 16:20:06,976] [ERROR] "POST /admin/goods/goodstype/add/ HTTP/1.1" 500 248433
[2022-06-04 16:24:14,139] [ERROR] Internal Server Error: /admin/jsi18n/
Traceback (most recent call last):
  File "/home/lqs/桌面/fresh-plus/dfresh/venv/lib/python3.10/site-packages/pymysql/connections.py", line 613, in connect
    sock = socket.create_connection(
  File "/usr/lib/python3.10/socket.py", line 845, in create_connection
    raise err
  File "/usr/lib/python3.10/socket.py", line 833, in create_connection
    sock.connect(sa)
TimeoutError: timed out

During handling of the above exception, another exception occurred:

Traceback (most recent call last):
  File "/home/lqs/桌面/fresh-plus/dfresh/venv/lib/python3.10/site-packages/django/db/backends/base/base.py", line 230, in ensure_connection
    self.connect()
  File "/home/lqs/桌面/fresh-plus/dfresh/venv/lib/python3.10/site-packages/django/utils/asyncio.py", line 25, in inner
    return func(*args, **kwargs)
  File "/home/lqs/桌面/fresh-plus/dfresh/venv/lib/python3.10/site-packages/django/db/backends/base/base.py", line 211, in connect
    self.connection = self.get_new_connection(conn_params)
  File "/home/lqs/桌面/fresh-plus/dfresh/venv/lib/python3.10/site-packages/django/utils/asyncio.py", line 25, in inner
    return func(*args, **kwargs)
  File "/home/lqs/桌面/fresh-plus/dfresh/venv/lib/python3.10/site-packages/django/db/backends/mysql/base.py", line 233, in get_new_connection
    connection = Database.connect(**conn_params)
  File "/home/lqs/桌面/fresh-plus/dfresh/venv/lib/python3.10/site-packages/pymysql/connections.py", line 353, in __init__
    self.connect()
  File "/home/lqs/桌面/fresh-plus/dfresh/venv/lib/python3.10/site-packages/pymysql/connections.py", line 664, in connect
    raise exc
pymysql.err.OperationalError: (2003, "Can't connect to MySQL server on '104.168.68.86' (timed out)")

The above exception was the direct cause of the following exception:

Traceback (most recent call last):
  File "/home/lqs/桌面/fresh-plus/dfresh/venv/lib/python3.10/site-packages/django/core/handlers/exception.py", line 47, in inner
    response = get_response(request)
  File "/home/lqs/桌面/fresh-plus/dfresh/venv/lib/python3.10/site-packages/django/core/handlers/base.py", line 181, in _get_response
    response = wrapped_callback(request, *callback_args, **callback_kwargs)
  File "/home/lqs/桌面/fresh-plus/dfresh/venv/lib/python3.10/site-packages/django/contrib/admin/sites.py", line 254, in wrapper
    return self.admin_view(view, cacheable)(*args, **kwargs)
  File "/home/lqs/桌面/fresh-plus/dfresh/venv/lib/python3.10/site-packages/django/utils/decorators.py", line 130, in _wrapped_view
    response = view_func(request, *args, **kwargs)
  File "/home/lqs/桌面/fresh-plus/dfresh/venv/lib/python3.10/site-packages/django/contrib/admin/sites.py", line 225, in inner
    if not self.has_permission(request):
  File "/home/lqs/桌面/fresh-plus/dfresh/venv/lib/python3.10/site-packages/django/contrib/admin/sites.py", line 199, in has_permission
    return request.user.is_active and request.user.is_staff
  File "/home/lqs/桌面/fresh-plus/dfresh/venv/lib/python3.10/site-packages/django/utils/functional.py", line 248, in inner
    self._setup()
  File "/home/lqs/桌面/fresh-plus/dfresh/venv/lib/python3.10/site-packages/django/utils/functional.py", line 384, in _setup
    self._wrapped = self._setupfunc()
  File "/home/lqs/桌面/fresh-plus/dfresh/venv/lib/python3.10/site-packages/django/contrib/auth/middleware.py", line 25, in <lambda>
    request.user = SimpleLazyObject(lambda: get_user(request))
  File "/home/lqs/桌面/fresh-plus/dfresh/venv/lib/python3.10/site-packages/django/contrib/auth/middleware.py", line 11, in get_user
    request._cached_user = auth.get_user(request)
  File "/home/lqs/桌面/fresh-plus/dfresh/venv/lib/python3.10/site-packages/django/contrib/auth/__init__.py", line 184, in get_user
    user = backend.get_user(user_id)
  File "/home/lqs/桌面/fresh-plus/dfresh/venv/lib/python3.10/site-packages/django/contrib/auth/backends.py", line 156, in get_user
    user = UserModel._default_manager.get(pk=user_id)
  File "/home/lqs/桌面/fresh-plus/dfresh/venv/lib/python3.10/site-packages/django/db/models/manager.py", line 85, in manager_method
    return getattr(self.get_queryset(), name)(*args, **kwargs)
  File "/home/lqs/桌面/fresh-plus/dfresh/venv/lib/python3.10/site-packages/django/db/models/query.py", line 435, in get
    num = len(clone)
  File "/home/lqs/桌面/fresh-plus/dfresh/venv/lib/python3.10/site-packages/django/db/models/query.py", line 262, in __len__
    self._fetch_all()
  File "/home/lqs/桌面/fresh-plus/dfresh/venv/lib/python3.10/site-packages/django/db/models/query.py", line 1354, in _fetch_all
    self._result_cache = list(self._iterable_class(self))
  File "/home/lqs/桌面/fresh-plus/dfresh/venv/lib/python3.10/site-packages/django/db/models/query.py", line 51, in __iter__
    results = compiler.execute_sql(chunked_fetch=self.chunked_fetch, chunk_size=self.chunk_size)
  File "/home/lqs/桌面/fresh-plus/dfresh/venv/lib/python3.10/site-packages/django/db/models/sql/compiler.py", line 1200, in execute_sql
    cursor = self.connection.cursor()
  File "/home/lqs/桌面/fresh-plus/dfresh/venv/lib/python3.10/site-packages/django/utils/asyncio.py", line 25, in inner
    return func(*args, **kwargs)
  File "/home/lqs/桌面/fresh-plus/dfresh/venv/lib/python3.10/site-packages/django/db/backends/base/base.py", line 270, in cursor
    return self._cursor()
  File "/home/lqs/桌面/fresh-plus/dfresh/venv/lib/python3.10/site-packages/django/db/backends/base/base.py", line 246, in _cursor
    self.ensure_connection()
  File "/home/lqs/桌面/fresh-plus/dfresh/venv/lib/python3.10/site-packages/django/utils/asyncio.py", line 25, in inner
    return func(*args, **kwargs)
  File "/home/lqs/桌面/fresh-plus/dfresh/venv/lib/python3.10/site-packages/django/db/backends/base/base.py", line 229, in ensure_connection
    with self.wrap_database_errors:
  File "/home/lqs/桌面/fresh-plus/dfresh/venv/lib/python3.10/site-packages/django/db/utils.py", line 90, in __exit__
    raise dj_exc_value.with_traceback(traceback) from exc_value
  File "/home/lqs/桌面/fresh-plus/dfresh/venv/lib/python3.10/site-packages/django/db/backends/base/base.py", line 230, in ensure_connection
    self.connect()
  File "/home/lqs/桌面/fresh-plus/dfresh/venv/lib/python3.10/site-packages/django/utils/asyncio.py", line 25, in inner
    return func(*args, **kwargs)
  File "/home/lqs/桌面/fresh-plus/dfresh/venv/lib/python3.10/site-packages/django/db/backends/base/base.py", line 211, in connect
    self.connection = self.get_new_connection(conn_params)
  File "/home/lqs/桌面/fresh-plus/dfresh/venv/lib/python3.10/site-packages/django/utils/asyncio.py", line 25, in inner
    return func(*args, **kwargs)
  File "/home/lqs/桌面/fresh-plus/dfresh/venv/lib/python3.10/site-packages/django/db/backends/mysql/base.py", line 233, in get_new_connection
    connection = Database.connect(**conn_params)
  File "/home/lqs/桌面/fresh-plus/dfresh/venv/lib/python3.10/site-packages/pymysql/connections.py", line 353, in __init__
    self.connect()
  File "/home/lqs/桌面/fresh-plus/dfresh/venv/lib/python3.10/site-packages/pymysql/connections.py", line 664, in connect
    raise exc
django.db.utils.OperationalError: (2003, "Can't connect to MySQL server on '104.168.68.86' (timed out)")
[2022-06-04 16:24:14,141] [ERROR] "GET /admin/jsi18n/ HTTP/1.1" 500 271729
