[2022-01-23 11:25:34,368] [ERROR] Internal Server Error: /detail/1
Traceback (most recent call last):
  File "/home/lqs/桌面/git/fresh/venv/lib/python3.8/site-packages/django/core/handlers/exception.py", line 47, in inner
    response = get_response(request)
  File "/home/lqs/桌面/git/fresh/venv/lib/python3.8/site-packages/django/core/handlers/base.py", line 181, in _get_response
    response = wrapped_callback(request, *callback_args, **callback_kwargs)
  File "/home/lqs/桌面/git/fresh/venv/lib/python3.8/site-packages/django/views/generic/base.py", line 69, in view
    return self.dispatch(request, *args, **kwargs)
  File "/home/lqs/桌面/git/fresh/venv/lib/python3.8/site-packages/django/views/generic/base.py", line 101, in dispatch
    return handler(request, *args, **kwargs)
  File "/home/lqs/桌面/git/fresh/dfresh/apps/goods/views.py", line 55, in get
    goods_list = GoodsSKU.objects.filter(goods=goods)
  File "/home/lqs/桌面/git/fresh/venv/lib/python3.8/site-packages/django/db/models/manager.py", line 85, in manager_method
    return getattr(self.get_queryset(), name)(*args, **kwargs)
  File "/home/lqs/桌面/git/fresh/venv/lib/python3.8/site-packages/django/db/models/query.py", line 974, in filter
    return self._filter_or_exclude(False, args, kwargs)
  File "/home/lqs/桌面/git/fresh/venv/lib/python3.8/site-packages/django/db/models/query.py", line 992, in _filter_or_exclude
    clone._filter_or_exclude_inplace(negate, args, kwargs)
  File "/home/lqs/桌面/git/fresh/venv/lib/python3.8/site-packages/django/db/models/query.py", line 999, in _filter_or_exclude_inplace
    self._query.add_q(Q(*args, **kwargs))
  File "/home/lqs/桌面/git/fresh/venv/lib/python3.8/site-packages/django/db/models/sql/query.py", line 1375, in add_q
    clause, _ = self._add_q(q_object, self.used_aliases)
  File "/home/lqs/桌面/git/fresh/venv/lib/python3.8/site-packages/django/db/models/sql/query.py", line 1396, in _add_q
    child_clause, needed_inner = self.build_filter(
  File "/home/lqs/桌面/git/fresh/venv/lib/python3.8/site-packages/django/db/models/sql/query.py", line 1302, in build_filter
    self.check_related_objects(join_info.final_field, value, join_info.opts)
  File "/home/lqs/桌面/git/fresh/venv/lib/python3.8/site-packages/django/db/models/sql/query.py", line 1134, in check_related_objects
    self.check_query_object_type(value, opts, field)
  File "/home/lqs/桌面/git/fresh/venv/lib/python3.8/site-packages/django/db/models/sql/query.py", line 1115, in check_query_object_type
    raise ValueError(
ValueError: Cannot query "盒装草莓": Must be "Goods" instance.
[2022-01-23 11:25:34,369] [ERROR] "GET /detail/1 HTTP/1.1" 500 126680
